Workbook

Sheet Coach Brief
A1: LONDON MARATHON 2027 — COACH BRIEF
A4: Race | B4: London Marathon, Sunday 25 April 2027
A5: Phase started | B5: 3 August 2026 (Base Building)
A7: ATHLETE
A8: Name | B8: Joe
A9: Age | B9: 28
A10: Height | B10: 6'4" (193 cm)
A11: Starting weight | B11: 18 st 11 lb (119.3 kg) — 3 Aug 2026
A12: Occupation | B12: Building Inspector (drives a lot, walks sites, climbs ladders)
A13: Previous injuries | B13: None
A14: Gym | B14: Doesn't currently go
A15: Running experience | B15: Very little; a few 5Ks years ago
A16: Biggest endurance achievement | B16: Walking marathon in Hoka Clifton 9s
A18: EQUIPMENT
A19: Watch | B19: Garmin Forerunner 255 Music
A20: Apps | B20: Garmin Connect, Strava (Garmin auto-syncs every run to Strava)
A21: Shoes | B21: Hoka Clifton 9
A23: DATA SOURCES (updated Aug 2026)
A24: Primary — run metrics | B24: Strava connector, auto-pulled: pace, HR, splits/laps, cadence, elevation, calories.
A25: Gap — wellness metrics | B25: Sleep score, Body Battery, resting HR trend, VO2max live only in Garmin Connect, which has no connector. Fill via Apple Health on iOS or weekly manual entry on the Health tab.
A26: Manual — every run | B26: RPE, pain/niggles, anything unusual. Joe reports this in chat; everything else is extracted automatically.
A28: COACHING PHILOSOPHY — priority order
A29: 1 | B29: Stay injury free
A30: 2 | B30: Build consistency
A31: 3 | B31: Lose weight gradually
A32: 4 | B32: Improve aerobic fitness
A33: 5 | B33: Complete London Marathon strongly
A34: Rule | B34: Never sacrifice injury prevention to progress faster. If in doubt, slow down.
A36: COMMUNICATION STYLE
A37: Preference | B37: Honest, evidence-based feedback: pace, HR, trends, comparisons. No generic motivational filler.
A38: Every run | B38: Analyse pace, HR, workout structure, weather, RPE, pain, shoe feedback, then decide: repeat or progress, based on recovery not a rigid plan.
A40: RUN NUMBERING | B40: Permanent IDs R001, R002... never reused or renumbered. Coach refers to runs by ID.
A42: CURRENT CONCERN | B42: Possible early shin splints (first appeared R002, mins 22-25). Do not progress running volume/intensity until pain is absent during walking and normal daily life.
A44: Weigh-in day | B44: Wednesday mornings — first thing after waking, before food/drink, minimal clothing, same scale.

Sheet Dashboard
A1: PROJECT LONDON 2027
A4: MARATHON COUNTDOWN | D4: TRAINING PHASE
A5: =MAX(0,DATE(2027,4,25)-TODAY())&" days" | D5: Base Building
A9: RUNS | C9: TOTAL KM | E9: LONGEST
A10: =COUNTA('Run Archive'!A2:A500) | C10: =ROUND(SUM('Run Archive'!G2:G500),2) | E10: =IFERROR(ROUND(MAX('Run Archive'!G2:G500),2),0)
A12: WEIGHT | C12: AVG HR | E12: CONSISTENCY
A13: =IFERROR(INT(LOOKUP(2,1/(Health!B5:B200<>""),Health!B5:B200))&" st "&ROUND(MOD(LOOKUP(2,1/(Health!B5:B200<>""),Health!B5:B200),1)*14,0)&" lb","—") | C13: =IFERROR(ROUND(AVERAGE('Run Archive'!J2:J500),0)&" bpm","—") | E13: =IFERROR(TEXT(COUNTIF('Current Week'!H5:H11,"Completed")/COUNTIFS('Current Week'!B5:B11,"<="&TODAY(),'Current Week'!H5:H11,"<>"),"0%"),"—")
A16: WEIGHT LOST SINCE START
A17: =IFERROR(ROUND(Health!B5-LOOKUP(2,1/(Health!B5:B200<>""),Health!B5:B200),2)&" st lost","—")
A20: SHOE MILEAGE (Hoka Clifton 9)
A21: =ROUND(SUMIFS('Run Archive'!G:G,'Run Archive'!T:T,"Hoka Clifton 9"),2)&" km"
A24: NEXT WORKOUT
A25: =IFERROR(INDEX('Current Week'!D5:D11,MATCH(_xlfn.MINIFS('Current Week'!B5:B11,'Current Week'!H5:H11,"Planned",'Current Week'!B5:B11,">="&TODAY()),'Current Week'!B5:B11,0))&" — "&INDEX('Current Week'!E5:E11,MATCH(_xlfn.MINIFS('Current Week'!B5:B11,'Current Week'!H5:H11,"Planned",'Current Week'!B5:B11,">="&TODAY()),'Current Week'!B5:B11,0)),"See Current Week tab")
A29: COACH STATUS
A30: =IFERROR(INDEX('Run Archive'!Z:Z,COUNTA('Run Archive'!A:A)),"")

Sheet Current Week
A1: WEEK 1 • 3–9 AUGUST 2026
A3: Goal: establish a safe baseline and finish every run with something left in reserve.
A4: Day | B4: Date | C4: Type | D4: Session | E4: Workout Details | F4: Target | G4: Notes | H4: Status
A5: Mon | B5: 46237 | C5: Run/Walk | D5: R001 | E5: 5 min walk + 8 × (2 min run / 2 min walk) + 5 min walk | F5: RPE 3–4 | G5: Completed at RPE 5; breathing settled. | H5: Completed
A6: Tue | B6: 46238 | C6: Rest | D6: Recovery | E6: Normal daily movement only | F6: Easy | G6: Monitor calves, Achilles, knees and feet. | H6: Planned
A7: Wed | B7: 46239 | C7: Run/Walk | D7: R002 | E7: 5 min walk + 8 × (2 min run / 2 min walk) + 5 min walk | F7: RPE 3–4 | G7: R002 complete. Shin pain at 22–25 min; strongest final interval. | H7: Completed
A8: Thu | B8: 46240 | C8: Travel | D8: 250-mile drive | E8: No formal training | F8: Recovery | G8: Short walk and mobility after driving. | H8: Planned
A9: Fri | B9: 46241 | C9: Rest/Walk | D9: Easy recovery | E9: Optional 20–30 min relaxed walk | F9: RPE 2 | G9: At parents' house. | H9: Planned
A10: Sat | B10: 46242 | C10: Walk | D10: Aerobic walk | E10: 45–60 min comfortable brisk walk | F10: RPE 3 | G10: No parkrun yet; build to continuous 5K first. | H10: Planned
A11: Sun | B11: 46243 | C11: Run/Walk | D11: Provisional R003 | E11: Repeat 2:2 × 8 only if shins pain-free in daily life | F11: RPE 3–4 | G11: R003 complete. RPE 6, HR elevated (heat/dehydration/alcohol), shin pain present but reduced vs R002. | H11: Completed

Sheet Run Archive
A1: Run ID | B1: Date | C1: Week Start | D1: Session Type | E1: Workout Structure | F1: Activity Name | G1: Distance (km) | H1: Moving Time | I1: Avg Pace (/km) | J1: Avg HR | K1: Max HR | L1: Elevation (m) | M1: Calories | N1: Cadence | O1: RPE | P1: Pain | Q1: Sleep Score | R1: Sleep (hrs) | S1: Weight (st) | T1: Shoes | U1: Weather/Context | V1: Breathing | W1: Shoe Feedback | X1: Body Feedback | Y1: Coach Analysis | Z1: Coach Decision | AA1: Next Workout | AB1: Strava Activity ID | AC1: Source | AD1: Elapsed Time (Strava)
A2: R001 | B2: 46237 | C2: 46237 | D2: Run/Walk | E2: 5 min warm-up walk + 8 × (2 min run / 2 min walk) + 5 min cool-down walk | F2: South Ribble - 2x2 8 times | G2: 3.92 | H2: 00:38:08 | I2: 00:09:43 | J2: 132 | K2: 175 | L2: 31 | M2: 431 | O2: 5 | P2: 0 | S2: 18.7857 | T2: Hoka Clifton 9 | U2: South Ribble; lunch run; sunny/partly cloudy; about 21–22°C; wind visible on Garmin | V2: Out of breath early, then settled and grew into the workout | W2: Shoes felt okay; heels seemed to roll inward slightly | X2: Could have completed another couple of intervals, probably at a slower pace | Y2: Controlled first session. The final running interval was the fastest, showing a sensible build rather than an early blow-up. | Z2: Repeat the same run/walk session. Monitor heel stability and next-day soreness. | AA2: R002: repeat 2 min run / 2 min walk × 8 | AB2: 19580879818 | AC2: Strava (auto) + Joe (RPE/pain/notes) | AD2: 00:40:01
A3: R002 | B3: 46239 | C3: 46237 | D3: Run/Walk | E3: 5 min warm-up walk + 8 × (2 min run / 2 min walk) + 5 min cool-down walk | F3: South Ribble - 2x2 8 times | G3: 4.11 | H3: 00:39:05 | I3: 00:09:30 | J3: 128 | K3: 170 | L3: 39 | M3: 427 | O3: 6 | S3: 18.7857 | T3: Hoka Clifton 9 | U3: South Ribble; morning run; windy; 16°C, feels 11°C; humidity 79%; WSW wind 28.8 km/h | V3: Felt strongest on the final 2-minute run | W3: No new shoe discomfort reported | X3: Body otherwise felt fine; shin pain appeared around minutes 22–25 | Y3: Clear efficiency improvement vs R001: 0.19 km farther, 13 sec/km faster and 4 bpm lower average HR over essentially identical elapsed time. The shin pain is the limiting factor, not aerobic effort. | Z3: Do not progress automatically. Reassess shins over 24–48 hours; progress only if walking and daily activity are pain-free. | AA3: Recovery / travel-day plan until shin response is known | AB3: 19610247354 | AC3: Strava (auto) + Joe (RPE/pain/notes) | AD3: 00:40:00
A4: R003 | B4: 46243 | C4: 46237 | D4: Run/Walk | E4: 5 min warm-up walk + 8 x (2 min run / 2 min walk) + 5 min cool-down walk | F4: Evening Run | G4: 4.0851 | H4: 00:39:39 | I4: 00:09:42 | J4: 137 | K4: 170 | L4: 23 | M4: 449 | O4: 6 | P4: Some, less than R002 - heavy legs/shins, not overly painful | T4: Hoka Clifton 9 | U4: Evening run, ~28C, delayed from earlier due to heat; weekend of alcohol/food beforehand | W4: No new shoe discomfort reported | X4: Heavy legs generally; shin discomfort present but reduced vs R002 | Y4: Pace essentially matched R001 (9:42 vs 9:43/km) and was 12 sec/km slower than R002, but avg HR was notably higher than both (137 vs 132 R001, 128 R002) despite less elevation gain (23m) than either prior run. Lap data shows HR climbing steadily through the session without recovering during walk intervals later on - consistent with heat and dehydration (alcohol + ~28C evening run) rather than a fitness or injury regression. Shin pain present but reduced from R002, a genuine improving trend. CORRECTION: Garmin sleep data shows the poor-sleep night (score 37, HRV 21, REM 3.4%) was actually two nights before R003 (7-8 Aug), not the night immediately before as first stated. No sleep record exists for the night directly before R003 (8-9 Aug). The two-nights-prior disruption, alongside the athlete's own report of a weekend of drinking, still supports cumulative dehydration/fatigue as context for the elevated HR, but this is weaker evidence than originally claimed. | Z4: Hold, not progress. Repeat identical structure for R004 (Wed 12 Aug). Continue monitoring shins in daily life through Tue; if pain has fully resolved by Wednesday, R004 proceeds as planned. If shin pain repeats at similar or worse level in R004, that is two of the last two sessions with unresolved pain and warrants recommending a physio assessment rather than continuing to self-manage. | AA4: R004: repeat 2 min run / 2 min walk x 8, Wed 12 Aug, contingent on continued shin improvement | AB4: 19673665126 | AC4: Strava (auto) + Joe (RPE/pain/notes) | AD4: 00:40:00
A5: R004 | B5: 46246.424 | C5: 46244 | D5: Run/Walk | E5: 5 min warm-up walk + 8 x (2 min run / 2 min walk) + 5 min cool-down walk (Garmin-scheduled workout ran final recovery interval AND a separate cooldown back-to-back - flagged by Joe, fixed for R005 onward: cooldown set to 0 min so the last recovery walk is the finish, matching how he does it manually) | F5: Morning Run | G5: 4.1699 | H5: 00:40:47 | I5: 00:09:47 | J5: 135 | K5: 177 | L5: 31 | M5: 448 | O5: 5 | P5: Minor discomfort lasting a couple of minutes, resolved, then good recovery - finished strong | Q5: 80 | R5: 6.9 | S5: 18.7571 | T5: Hoka Clifton 9 | U5: Late morning run, no heat or travel factors. Joe reported a heavy dinner the night before. | W5: No new shoe discomfort reported | X5: Little to no shin pain, felt strong through the finish - farthest session yet | Y5: Farthest session yet (4.17 km vs previous best 4.11 km, R002), avg HR 135 - a genuinely stronger reading than R003's heat-elevated 137, since today had no heat factor. Pace (9:47/km) essentially matches R003 (9:42/km) and R002 (9:44/km). Lap data (Strava) shows the warmup lap averaged 95 bpm, run/walk cycles built steadily from ~125 to ~150 bpm across the session (normal cardiac drift, not a red flag), and the added cooldown lap dropped back to 124 bpm - HR behaved exactly as expected for a well-tolerated session. RPE 5/10, comfortable throughout. Shin pain was minimal: one brief couple-minute flare that resolved, followed by good recovery and a strong finish - a clear improvement on R002 and R003. This is the first fully clean session of the block (RPE <=6, no worsening pain), but R003 still had some pain, so it only counts as one - the run/walk ladder rule needs two consecutive clean sessions before advancing. | Z5: Hold, not progress. R005 (Thu 13 Aug, already scheduled to Garmin) stays an identical repeat of 2 min run / 2 min walk x 8, not a step up to 3:2 x6 - R004 is only the first clean session and the rule needs two in a row. If R005 also comes back RPE <=6 with no worsening pain and clears within 24h, R006 can move to the next rung (3 min run / 2 min walk x 6). | AA5: R005: repeat 2 min run / 2 min walk x 8, Thu 13 Aug, scheduled to Garmin with cooldown fixed to 0 min | AB5: 19708313053 | AC5: Strava (auto) + Garmin Connect (auto) + Joe (RPE/pain/notes) | AD5: 00:42:00

Sheet Interval Detail
A1: Run ID | B1: Date | C1: Interval | D1: Step Type | E1: Duration | F1: Distance (mi) | G1: Avg Pace (min/mi) | H1: Distance (km) | I1: Avg Pace (/km) | J1: Notes
A2: R001 | B2: 46237 | C2: 1 | D2: Run | E2: 00:02:00 | F2: 0.14 | G2: 13:59 | H2: 0.2253 | I2: 8:41 | J2: Eased into session
A3: R001 | B3: 46237 | C3: 2 | D3: Run | E3: 00:02:00 | F3: 0.15 | G3: 13:25 | H3: 0.2414 | I3: 8:20
A4: R001 | B4: 46237 | C4: 3 | D4: Run | E4: 00:02:00 | F4: 0.16 | G4: 12:22 | H4: 0.2575 | I4: 7:41
A5: R001 | B5: 46237 | C5: 4 | D5: Run | E5: 00:02:00 | F5: 0.15 | G5: 12:57 | H5: 0.2414 | I5: 8:03
A6: R001 | B6: 46237 | C6: 5 | D6: Run | E6: 00:02:00 | F6: 0.15 | G6: 12:56 | H6: 0.2414 | I6: 8:02
A7: R001 | B7: 46237 | C7: 6 | D7: Run | E7: 00:02:00 | F7: 0.15 | G7: 13:25 | H7: 0.2414 | I7: 8:20
A8: R001 | B8: 46237 | C8: 7 | D8: Run | E8: 00:02:00 | F8: 0.16 | G8: 12:53 | H8: 0.2575 | I8: 8:00
A9: R001 | B9: 46237 | C9: 8 | D9: Run | E9: 00:02:00 | F9: 0.17 | G9: 12:00 | H9: 0.2736 | I9: 7:27 | J9: Fastest interval; finished strongly
A10: R001 | B10: 46237 | C10: 1 | D10: Recovery | E10: 00:02:00 | F10: 0.1 | G10: 19:51 | H10: 0.1609
A11: R001 | B11: 46237 | C11: 2 | D11: Recovery | E11: 00:02:00 | F11: 0.11 | G11: 18:57 | H11: 0.177
A12: R001 | B12: 46237 | C12: 3 | D12: Recovery | E12: 00:02:00 | F12: 0.11 | G12: 18:51 | H12: 0.177
A13: R001 | B13: 46237 | C13: 4 | D13: Recovery | E13: 00:02:00 | F13: 0.1 | G13: 19:04 | H13: 0.1609
A14: R001 | B14: 46237 | C14: 5 | D14: Recovery | E14: 00:02:00 | F14: 0.11 | G14: 18:49 | H14: 0.177
A15: R001 | B15: 46237 | C15: 6 | D15: Recovery | E15: 00:02:00 | F15: 0.11 | G15: 19:00 | H15: 0.177
A16: R001 | B16: 46237 | C16: 7 | D16: Recovery | E16: 00:02:00 | F16: 0.11 | G16: 17:43 | H16: 0.177
A17: R002 | B17: 46239 | C17: 1 | D17: Run | E17: 00:02:00 | F17: 0.14 | G17: 13:53 | H17: 0.2253 | I17: 8:38 | J17: Slow opening interval
A18: R002 | B18: 46239 | C18: 2 | D18: Run | E18: 00:02:00 | F18: 0.17 | G18: 11:34 | H18: 0.2736 | I18: 7:11
A19: R002 | B19: 46239 | C19: 3 | D19: Run | E19: 00:02:00 | F19: 0.18 | G19: 11:16 | H19: 0.2897 | I19: 7:00 | J19: Fastest early interval
A20: R002 | B20: 46239 | C20: 4 | D20: Run | E20: 00:02:00 | F20: 0.17 | G20: 11:51 | H20: 0.2736 | I20: 7:22
A21: R002 | B21: 46239 | C21: 5 | D21: Run | E21: 00:02:00 | F21: 0.17 | G21: 12:03 | H21: 0.2736 | I21: 7:29
A22: R002 | B22: 46239 | C22: 6 | D22: Run | E22: 00:02:00 | F22: 0.16 | G22: 12:43 | H22: 0.2575 | I22: 7:54 | J22: Shin pain period began around here
A23: R002 | B23: 46239 | C23: 7 | D23: Run | E23: 00:02:00 | F23: 0.14 | G23: 13:50 | H23: 0.2253 | I23: 8:36 | J23: Slowed while managing shin pain
A24: R002 | B24: 46239 | C24: 8 | D24: Run | E24: 00:02:00 | F24: 0.18 | G24: 11:18 | H24: 0.2897 | I24: 7:01 | J24: Felt best; strong finish
A25: R002 | B25: 46239 | C25: 1 | D25: Recovery | E25: 00:02:00 | F25: 0.12 | G25: 17:10 | H25: 0.1931
A26: R002 | B26: 46239 | C26: 2 | D26: Recovery | E26: 00:02:00 | F26: 0.11 | G26: 17:56 | H26: 0.177
A27: R002 | B27: 46239 | C27: 3 | D27: Recovery | E27: 00:02:00 | F27: 0.1 | G27: 19:39 | H27: 0.1609
A28: R002 | B28: 46239 | C28: 4 | D28: Recovery | E28: 00:02:00 | F28: 0.1 | G28: 20:35 | H28: 0.1609
A29: R002 | B29: 46239 | C29: 5 | D29: Recovery | E29: 00:02:00 | F29: 0.09 | G29: 23:11 | H29: 0.1448
A30: R002 | B30: 46239 | C30: 6 | D30: Recovery | E30: 00:02:00 | F30: 0.1 | G30: 20:52 | H30: 0.1609
A31: R002 | B31: 46239 | C31: 7 | D31: Recovery | E31: 00:02:00 | F31: 0.1 | G31: 19:39 | H31: 0.1609
A32: R003 | B32: 46243 | C32: 1 | D32: Run | E32: 00:02:00 | F32: 0.16 | H32: 0.2576 | I32: 13:56
A33: R003 | B33: 46243 | C33: 2 | D33: Run | E33: 00:02:00 | F33: 0.17 | H33: 0.2735 | I33: 12:23
A34: R003 | B34: 46243 | C34: 3 | D34: Run | E34: 00:02:00 | F34: 0.18 | H34: 0.2859 | I34: 11:56
A35: R003 | B35: 46243 | C35: 4 | D35: Run | E35: 00:02:00 | F35: 0.18 | H35: 0.2879 | I35: 11:52
A36: R003 | B36: 46243 | C36: 5 | D36: Run | E36: 00:02:00 | F36: 0.17 | H36: 0.2758 | I36: 12:22
A37: R003 | B37: 46243 | C37: 6 | D37: Run | E37: 00:02:00 | F37: 0.16 | H37: 0.2503 | I37: 13:37
A38: R003 | B38: 46243 | C38: 7 | D38: Run | E38: 00:02:00 | F38: 0.15 | H38: 0.2475 | I38: 13:47
A39: R003 | B39: 46243 | C39: 8 | D39: Run | E39: 00:02:00 | F39: 0.16 | H39: 0.2643 | I39: 12:53 | J39: Fastest late interval despite cardiac drift
A40: R003 | B40: 46243 | C40: 1 | D40: Recovery | E40: 00:02:00 | F40: 0.11 | H40: 0.1711
...

Sheet Health
A1: HEALTH & RECOVERY
A4: Date | B4: Weight (st) | C4: Weight (kg) | D4: Change from Start (st) | E4: Sleep Score | F4: Sleep (hrs) | G4: Resting HR | H4: Fatigue (1–10) | I4: Pain/Niggles | J4: Notes
A5: 46237 | B5: 18.7857 | C5: =B5*6.35029318 | D5: =IF(B5="","",B5-$B$5) | E5: 74 | F5: 5.95 | I5: None reported | J5: Garmin sleep, night before R001: score 74 (Fair), short (5.95h, incl. a nap), HRV 39ms.
A6: 46239 | B6: 18.5 | C6: =B6*6.35029318 | D6: =IF(B6="","",B6-$B$5) | E6: 91 | F6: 7.65 | J6: Garmin sleep, night immediately before R002: score 91 (Excellent), 7.65h, HRV 36ms.
A7: 46238 | C7: =B7*6.35029318 | D7: =IF(B7="","",B7-$B$5) | E7: 89 | F7: 8.07 | J7: Garmin sleep, night of 3-4 Aug (two nights before R002): score 89 (Good), 8.07h, HRV 30ms.
A8: 46242 | C8: =B8*6.35029318 | D8: =IF(B8="","",B8-$B$5) | E8: 37 | F8: 6.88 | J8: CORRECTED LABEL: this is the night of 7-8 Aug (Fri-Sat), TWO nights before R003, not the night immediately before as originally logged. Score 37 (Poor), HRV 21ms, REM 3.4%, within the reported weekend of drinking. No Garmin sleep record exists for the night immediately before R003 (8-9 Aug) - query returned empty.
A9: 46240 | C9: =B9*6.35029318 | D9: =IF(B9="","",B9-$B$5) | E9: 82 | F9: 7.12 | J9: Garmin sleep: score 82 (Good), 7.12h, HRV 32ms.
A10: 46241 | C10: =B10*6.35029318 | D10: =IF(B10="","",B10-$B$5) | E10: 59 | F10: 6.73 | J10: Garmin sleep: score 59 (Poor), 6.73h, HRV 22ms.
A11: 46244 | C11: =B11*6.35029318 | D11: =IF(B11="","",B11-$B$5) | E11: 88 | F11: 8.05 | J11: Garmin sleep, night after R003: score 88 (Good), 8.05h, HRV 29ms.
A12: 46246 | B12: 18.7571 | C12: =B12*6.35029318 | D12: =IF(B12="","",B12-$B$5) | E12: 80 | F12: 6.9 | G12: 52
C13: =B13*6.35029318 | D13: =IF(B13="","",B13-$B$5)
C14: =B14*6.35029318 | D14: =IF(B14="","",B14-$B$5)
C15: =B15*6.35029318 | D15: =IF(B15="","",B15-$B$5)
C16: =B16*6.35029318 | D16: =IF(B16="","",B16-$B$5)
C17: =B17*6.35029318 | D17: =IF(B17="","",B17-$B$5)
C18: =B18*6.35029318 | D18: =IF(B18="","",B18-$B$5)
C19: =B19*6.35029318 | D19: =IF(B19="","",B19-$B$5)
C20: =B20*6.35029318 | D20: =IF(B20="","",B20-$B$5)
C21: =B21*6.35029318 | D21: =IF(B21="","",B21-$B$5)
C22: =B22*6.35029318 | D22: =IF(B22="","",B22-$B$5)
C23: =B23*6.35029318 | D23: =IF(B23="","",B23-$B$5)
C24: =B24*6.35029318 | D24: =IF(B24="","",B24-$B$5)
... C64: =B64*6.35029318 | D64: =IF(B64="","",B64-$B$5)

Sheet Progress
A1: PROGRESS LAB
A4: Metric | B4: Current | C4: Starting | D4: Change | E4: Current (readable) | F4: Change (readable)
A5: Weight (st) | B5: =IFERROR(LOOKUP(2,1/(Health!B5:B200<>""),Health!B5:B200),"") | C5: 18.7857 | D5: =IF(B5="","",B5-C5) | E5: =INT(B5)&" st "&ROUND(MOD(B5,1)*14,0)&" lb" | F5: =IF(D5<=0,ROUND(-D5*14,0)&" lb lost",ROUND(D5*14,0)&" lb gained")
A6: Total distance (km) | B6: =ROUND(SUM('Run Archive'!G2:G500),2) | C6: 0 | D6: =B6-C6
A7: Longest run (km) | B7: =IFERROR(ROUND(MAX('Run Archive'!G2:G500),2),0) | C7: 0 | D7: =B7-C7
A8: Average HR | B8: =IFERROR(ROUND(AVERAGE('Run Archive'!J2:J500),0),"") | C8: 133 | D8: =B8-C8
A9: Runs completed | B9: =COUNTA('Run Archive'!A2:A500) | C9: 0 | D9: =B9-C9

Sheet Milestones
A1: MILESTONES
A4: Milestone | B4: Status | C4: Date | D4: Result | E4: Run # | F4: Story
A5: Official Run #1 | B5: Achieved | C5: 46237 | D5: 3.92 km run/walk | E5: R001 | F5: The marathon project officially began.
A6: First efficiency improvement | B6: Achieved | C6: 46239 | D6: Farther + lower HR than R001 | E6: R002 | F6: First repeat workout showing measurable aerobic efficiency improvement.
A7: First continuous 20 min | B7: Not yet
A8: First continuous 30 min | B8: Not yet
A9: First continuous 5K | B9: Not yet
A10: First parkrun | B10: Not yet
A11: First 10K | B11: Not yet
A12: 100 km total | B12: Not yet
A13: First half marathon | B13: Not yet
A14: First 20-mile run | B14: Not yet
A15: 1 stone lost | B15: Not yet
A16: 2 stone lost | B16: Not yet
A17: London Marathon 2027 | B17: Not yet | C17: 46502

Sheet Gear
A1: GEAR
A4: Item | B4: Brand/Model | C4: Start Date | D4: Known Starting km | E4: Project km | F4: Replace Around | G4: Status | H4: Notes | I4: Total km (est.)
A5: Running Shoes | B5: Hoka Clifton 9 | C5: 46237 | D5: 300 | E5: =ROUND(SUMIFS('Run Archive'!G:G,'Run Archive'!T:T,B5),2) | F5: 700 | G5: Active — ~44% through typical lifespan (300km known + project km, against a 700km replace estimate) | H5: Used for training walks, a 26.2-mile walking marathon (17 May 2025), and running since June 2024. Strava history (runs + walks ≥ 3km, June 2024–Aug 2026) totalled 321.26 km; logged conservatively at 300 km. Add gear in Strava (Settings > My Gear) going forward so mileage tracks automatically and precisely. | I5: =D5+E5

Sheet Coach Journal
A1: COACH JOURNAL
A4: Date | B4: Entry Type | C4: Observation | D4: Evidence | E4: Decision | F4: Status
A5: 46237 | B5: Run Review | C5: Breathing was difficult early but settled as the run progressed. | D5: RPE 5; HR increased gradually; athlete reported growing into the session. | E5: Repeat the session rather than progress immediately. | F5: Watching
A6: 46237 | B6: Gear | C6: Heels appeared to roll inward slightly in Clifton 9s. | D6: Subjective shoe feedback; no pain reported. | E6: Monitor after each run; no shoe or orthotic change yet. | F6: Watching
A7: 46237 | B7: Training Decision | C7: Athlete finished with reserve. | D7: Could have completed another couple of intervals at a slower pace. | E7: Keep Run #2 identical and aim for lower perceived effort. | F7: Active
A8: 46239 | B8: Run Review | C8: R002 improved distance and average HR over identical elapsed time. | D8: 4.11 km vs 3.92 km; 128 bpm vs 132 bpm; final interval was one of the fastest. | E8: Recognise aerobic improvement but do not increase load until shin symptoms settle. | F8: Watching
A9: 46239 | B9: Health | C9: Shin pain appeared around minutes 22–25. | D9: Athlete reported body otherwise felt fine and completed the final interval strongly. | E9: Reassess pain during walking and daily activity before scheduling the next run. | F9: Active
A10: 46239 | B10: Data Update | C10: R002 RPE confirmed at 6/10 by athlete. Cadence flat between R001 (63.1) and R002 (63.9) — low for running, plausible contributor to shin loading given athlete's height, alongside the heel-roll noted in R001. | D10: Interval splits show R002 slowed at intervals 6-7 (shin pain onset) then produced the fastest interval of the run at interval 8 — flagged as possible gait compensation rather than pure fitness gain, pending clarity. | E10: No conclusion drawn on cadence; noted for future reference. Progression decision unchanged: wait for pain-free daily life before R003. | F10: Watching
A11: 46239 | B11: Gear | C11: Hoka Clifton 9 shoe mileage estimated from full Strava history (runs + walks ≥3km, June 2024–Aug 2026): 321.26 km actual, logged conservatively at 300 km. Total with project mileage now ~308 km against a 700 km replace estimate. | D11: Shoes are roughly 44% through typical lifespan, not fresh. This sits alongside low cadence (~63/min) and heel-roll noted in R001 as another plausible contributor to R002's shin pain — reduced cushioning/support, not just form. | E11: No action yet. If shin pain recurs past R003, shoe wear should be part of that conversation alongside gait, not dismissed as coincidence. | F11: Watching
A12: 46243 | B12: Run Review | C12: R003 run in ~28C heat after a weekend of alcohol and three 250-mile drives. Pace matched R001, HR notably elevated vs both prior runs despite less climbing. | D12: 9:42/km pace (vs 9:43 R001, 9:31 R002); avg HR 137 (vs 132 R001, 128 R002); elevation only 23m (least of the three runs); HR climbed steadily through session without recovering in walk intervals. | E12: Elevated HR attributed to heat/dehydration/alcohol, not fitness regression. Shin pain present but reduced vs R002 - genuine improving trend, not resolved. | F12: Watching
A13: 46243 | B13: Training Decision | C13: Shin pain improving (R002 -> R003) but not yet resolved. RPE 6/10, described as heavy legs and shins. | D13: Athlete report: 'not much pain, less pain than R002... heavy legs and shins, not overly painful.' | E13: Hold, not progress. R004 repeats identical structure Wed 12 Aug, contingent on continued shin improvement through Tue. A repeat of unresolved pain in R004 (two of two most recent sessions) would move this to recommending a physio assessment. | F13: Active
A14: 46244 | B14: Gear | C14: In-store machine gait scan (Sports Direct, not a clinician) recommends a neutral shoe. Candidates given: Adidas Adizero Evo SL, ASICS Gel Nimbus 28, On Cloudsurfer Max, Nike Vomero 18, On Cloudmonster 2, ASICS Novablast 6. | D14: Machine screening, not a professional assessment - treat as one data point, not a diagnosis. Neutral recommendation is at least consistent with current Hoka Clifton 9 (also neutral). Adizero Evo SL is a lighter tempo-leaning shoe, not comparable to the others as a daily base-building trainer. | E14: No shoe change before R004 - keep the shin pain recovery test clean. If shin pain doesn't resolve, escalate to an actual physio assessment, not another machine scan. Revisit shoe choice separately once R004 outcome is known. | F14: Watching
A15: 46246 | B15: Data Update | C15: R004 done - 4.17 km, avg HR 135, RPE 5/10. Little to no shin pain (brief couple-minute flare, resolved). First fully clean session of the block. R005 (13 Aug) scheduled as an identical repeat, not a progression - rule needs two consecutive clean sessions before advancing the run/walk ladder to 3:2 x6. | D15: Farthest distance yet; HR lower than R003 (heat-affected) despite similar pace; laps confirm normal cardiac drift.
A16: 46246 | B16: Reference | C16: Athlete's most recent verified 5K PB: 33:54, set 24 May 2024 - over 2 years before this training block started, predating the current shin issue and current fitness/weight. Useful as a rough historical sanity check only, not a basis for a current-fitness prediction. | D16: Athlete-reported date; matches Garmin's stored personal record (33:54, no date on record). Will be superseded once a genuine current-block 5K time exists (see Race Plan tab, prediction panel note).

Sheet Data Guide
A1: HOW THIS TRAINING LOG WORKS — v2 (Cowork + Strava)
A4: Sheet | B4: Purpose | C4: Updated When | D4: What You Need To Do
A5: Coach Brief | B5: The full coaching contract: athlete profile, philosophy, comms style, current concern. | C5: Rarely — only if circumstances change | D5: Tell me if anything here goes out of date.
A6: Dashboard | B6: Phone-friendly snapshot. Also mirrored live in the Cowork dashboard artifact. | C6: After every run I log | D6: Nothing — quick view.
A7: Current Week | B7: Live training plan and status. | C7: After each workout or plan change | D7: Follow the next planned session.
A8: Run Archive | B8: Permanent database of every run: Strava metrics + your RPE/pain/notes + my analysis. | C8: After every run | D8: Tell me: RPE, pain, anything unusual. I pull the rest from Strava.
A9: Interval Detail | B9: Every interval/lap for structured workouts. | C9: After every run | D9: Nothing — pulled from Strava laps.
A10: Health | B10: Weight, sleep, resting HR, recovery trend. | C10: Weekly or when you tell me | D10: Send me a weigh-in weekly, or your Apple Health sleep/RHR on iOS.
A11: Progress | B11: Rolling KPI vs start. | C11: Automatically | D11: Nothing.
A12: Milestones | B12: Big achievements and story moments. | C12: When achieved | D12: Nothing — I'll flag them.
A13: Gear | B13: Shoe mileage and replacement estimate. | C13: After every run | D13: Optional: add your shoes as Gear in Strava so mileage cross-checks automatically.
A14: Coach Journal | B14: Long-term patterns, concerns, decisions — the reasoning trail. | C14: Whenever a pattern emerges | D14: Be honest about how you feel.
A16: Workflow:
A17: 1. Run it. 2. Tell me here (Cowork, on your Mac) or in the Claude app (phone): RPE, pain, anything unusual.
A18: 3. I pull the Strava data, update this file, refresh the live dashboard, and give you the coaching call: repeat or progress.
A19: 4. The live dashboard (Cowork Artifacts view) is always current on this Mac — open it here for the plan-vs-actual view. It doesn't sync to phone; this is a laptop-based workflow by choice.
